<?xml version="1.0" ?>
<!-- =================================================================================== -->
<!-- |    This document was autogenerated by xacro from src/thor_urdf/urdf/thor.urdf.xacro | -->
<!-- |    EDITING THIS FILE BY HAND IS NOT RECOMMENDED                                 | -->
<!-- =================================================================================== -->
<robot name="thor_arm">
  <gazebo>
    <plugin filename="libgazebo_ros2_control.so" name="gazebo_ros2_control">
      <robot_param>robot_description</robot_param>
      <robot_param_node>robot_state_publisher</robot_param_node>
      <parameters>/home/salman/GryphonEC-ROS2/ws_thor/install/thor_controller/share/thor_controller/config/thor_controllers.yaml</parameters>
    </plugin>
  </gazebo>
  <ros2_control name="RobotSystem" type="system">
    <!-- HARDWARE -->
    <hardware>
      <plugin>gazebo_ros2_control/GazeboSystem</plugin>
    </hardware>
    <joint name="gripperbase_to_armgearleft">
      <param name="mimic">gripperbase_to_armgearright</param>
      <param name="multiplier">-1</param>
    </joint>
    <!-- JOINTS -->
    <joint name="joint_1">
      <command_interface name="position"/>
      <command_interface name="velocity"/>
      <state_interface name="position"/>
      <state_interface name="velocity"/>
    </joint>
    <joint name="joint_2">
      <command_interface name="position"/>
      <command_interface name="velocity"/>
      <state_interface name="position"/>
      <state_interface name="velocity"/>
    </joint>
    <joint name="joint_3">
      <command_interface name="position"/>
      <command_interface name="velocity"/>
      <state_interface name="position"/>
      <state_interface name="velocity"/>
    </joint>
    <joint name="joint_4">
      <command_interface name="position"/>
      <command_interface name="velocity"/>
      <state_interface name="position"/>
      <state_interface name="velocity"/>
    </joint>
    <joint name="joint_5">
      <command_interface name="position"/>
      <command_interface name="velocity"/>
      <state_interface name="position"/>
      <state_interface name="velocity"/>
    </joint>
    <joint name="gripperbase_to_armgearright">
      <command_interface name="position"/>
      <command_interface name="velocity"/>
      <state_interface name="position"/>
      <state_interface name="velocity"/>
    </joint>
  </ros2_control>
  <!-- Material definitions -->
  <material name="silver">
    <color rgba="0.700 0.700 0.700 1.0"/>
  </material>
  <!-- Links -->
  <link name="world"/>
  <link name="base_link">
    <inertial>
      <origin rpy="0 0 0" xyz="2.6075162618733064e-09 -0.029687845824987256 0.05035622678340518"/>
      <mass value="8.760837729915295"/>
      <inertia ixx="0.055534" ixy="0.0" ixz="0.0" iyy="0.036307" iyz="-0.011146" izz="0.037464"/>
    </inertial>
    <visual>
      <origin rpy="0 0 0" xyz="0 0 0"/>
      <geometry>
        <mesh filename="package://thor_urdf/meshes/base_link.stl" scale="0.001 0.001 0.001"/>
      </geometry>
      <material name="silver"/>
    </visual>
    <collision>
      <origin rpy="0 0 0" xyz="0 0 0"/>
      <geometry>
        <mesh filename="package://thor_urdf/meshes/base_link.stl" scale="0.001 0.001 0.001"/>
      </geometry>
    </collision>
  </link>
  <link name="link_1">
    <inertial>
      <origin rpy="0 0 0" xyz="-0.0002522803737960238 -0.06081817480908806 0.07933683412425585"/>
      <mass value="36.4482470253964"/>
      <inertia ixx="0.220238" ixy="0.000816" ixz="0.00101" iyy="0.141934" iyz="-0.010654" izz="0.195048"/>
    </inertial>
    <visual>
      <origin rpy="0 0 0" xyz="0.0 -0.0 -0.19"/>
      <geometry>
        <mesh filename="package://thor_urdf/meshes/Waist_1.stl" scale="0.001 0.001 0.001"/>
      </geometry>
      <material name="silver"/>
    </visual>
    <collision>
      <origin rpy="0 0 0" xyz="0.0 -0.0 -0.19"/>
      <geometry>
        <mesh filename="package://thor_urdf/meshes/Waist_1.stl" scale="0.001 0.001 0.001"/>
      </geometry>
    </collision>
  </link>
  <link name="link_2">
    <inertial>
      <origin rpy="0 0 0" xyz="-0.05556645527562071 -0.004167729265803565 3.3002623928135577e-07"/>
      <mass value="62.39457105281159"/>
      <inertia ixx="1.477617" ixy="0.016793" ixz="-0.0" iyy="0.174618" iyz="0.0" izz="1.429036"/>
    </inertial>
    <visual>
      <origin rpy="0 0 0" xyz="0.07 -0.026322 -0.376322"/>
      <geometry>
        <mesh filename="package://thor_urdf/meshes/Shoulder_1.stl" scale="0.001 0.001 0.001"/>
      </geometry>
      <material name="silver"/>
    </visual>
    <collision>
      <origin rpy="0 0 0" xyz="0.07 -0.026322 -0.376322"/>
      <geometry>
        <mesh filename="package://thor_urdf/meshes/Shoulder_1.stl" scale="0.001 0.001 0.001"/>
      </geometry>
    </collision>
  </link>
  <link name="link_3">
    <inertial>
      <origin rpy="0 0 0" xyz="0.052001488366736424 0.015387963557426054 2.295063472990133e-06"/>
      <mass value="26.84125839669147"/>
      <inertia ixx="0.324303" ixy="1e-06" ixz="-0.0" iyy="0.046323" iyz="-1.1e-05" izz="0.326785"/>
    </inertial>
    <visual>
      <origin rpy="0 0 0" xyz="0.07 -0.251322 -0.376322"/>
      <geometry>
        <mesh filename="package://thor_urdf/meshes/Elbow_v1_1.stl" scale="0.001 0.001 0.001"/>
      </geometry>
      <material name="silver"/>
    </visual>
    <collision>
      <origin rpy="0 0 0" xyz="0.07 -0.251322 -0.376322"/>
      <geometry>
        <mesh filename="package://thor_urdf/meshes/Elbow_v1_1.stl" scale="0.001 0.001 0.001"/>
      </geometry>
    </collision>
  </link>
  <link name="link_4">
    <inertial>
      <origin rpy="0 0 0" xyz="-0.028000182710083837 0.0023134756758433905 -2.0573877996199474e-05"/>
      <mass value="0.07336127644204224"/>
      <inertia ixx="4e-06" ixy="-0.0" ixz="-0.0" iyy="1.4e-05" iyz="-0.0" izz="1.6e-05"/>
    </inertial>
    <visual>
      <origin rpy="0 0 0" xyz="-0.01 -0.476322 -0.376322"/>
      <geometry>
        <mesh filename="package://thor_urdf/meshes/Wrist_T_shape_v1_1.stl" scale="0.001 0.001 0.001"/>
      </geometry>
      <material name="silver"/>
    </visual>
    <collision>
      <origin rpy="0 0 0" xyz="-0.01 -0.476322 -0.376322"/>
      <geometry>
        <mesh filename="package://thor_urdf/meshes/Wrist_T_shape_v1_1.stl" scale="0.001 0.001 0.001"/>
      </geometry>
    </collision>
  </link>
  <link name="link_5">
    <inertial>
      <origin rpy="0 0 0" xyz="-1.9698045254992747e-07 0.04756806709239264 2.6795981544758263e-08"/>
      <mass value="0.6360331426782216"/>
      <inertia ixx="0.000418" ixy="-0.0" ixz="-0.0" iyy="0.00015" iyz="-0.0" izz="0.000404"/>
    </inertial>
    <visual>
      <origin rpy="0 0 0" xyz="0.018 -0.498134 -0.376318"/>
      <geometry>
        <mesh filename="package://thor_urdf/meshes/Wrist_gripper_base_v2_1.stl" scale="0.001 0.001 0.001"/>
      </geometry>
      <material name="silver"/>
    </visual>
    <collision>
      <origin rpy="0 0 0" xyz="0.018 -0.498134 -0.376318"/>
      <geometry>
        <mesh filename="package://thor_urdf/meshes/Wrist_gripper_base_v2_1.stl" scale="0.001 0.001 0.001"/>
      </geometry>
    </collision>
  </link>
  <link name="gripper_mid_point">
    <inertial>
      <origin rpy="0 0 0" xyz="0 0 0"/>
      <mass value="0.01"/>
      <inertia ixx="1.0" ixy="0.0" ixz="0.0" iyy="1.0" iyz="0.0" izz="1.0"/>
    </inertial>
  </link>
  <link name="gripper_finger_right">
    <inertial>
      <origin rpy="0 0 0" xyz="0.005010907689285325 0.007530308144696352 3.1698777935851297e-08"/>
      <mass value="0.04489078009580989"/>
      <inertia ixx="1e-05" ixy="-3e-06" ixz="0.0" iyy="3e-06" iyz="-0.0" izz="1.1e-05"/>
    </inertial>
    <visual>
      <origin rpy="0 0 0" xyz="0.008258 -0.579592 -0.376318"/>
      <geometry>
        <mesh filename="package://thor_urdf/meshes/Wrist_r_gripper_v1_1.stl" scale="0.001 0.001 0.001"/>
      </geometry>
      <material name="silver"/>
    </visual>
    <collision>
      <origin rpy="0 0 0" xyz="0.008258 -0.579592 -0.376318"/>
      <geometry>
        <mesh filename="package://thor_urdf/meshes/Wrist_r_gripper_v1_1.stl" scale="0.001 0.001 0.001"/>
      </geometry>
    </collision>
  </link>
  <link name="gripper_finger_left">
    <inertial>
      <origin rpy="0 0 0" xyz="-0.005009888223430386 0.0075296833236281335 5.85669156838442e-07"/>
      <mass value="0.04488910182418366"/>
      <inertia ixx="1e-05" ixy="3e-06" ixz="0.0" iyy="3e-06" iyz="-0.0" izz="1.1e-05"/>
    </inertial>
    <visual>
      <origin rpy="0 0 0" xyz="0.027743 -0.579592 -0.376318"/>
      <geometry>
        <mesh filename="package://thor_urdf/meshes/Wrist_l_gripper_v1_1.stl" scale="0.001 0.001 0.001"/>
      </geometry>
      <material name="silver"/>
    </visual>
    <collision>
      <origin rpy="0 0 0" xyz="0.027743 -0.579592 -0.376318"/>
      <geometry>
        <mesh filename="package://thor_urdf/meshes/Wrist_l_gripper_v1_1.stl" scale="0.001 0.001 0.001"/>
      </geometry>
    </collision>
  </link>
  <!-- Joints -->
  <joint name="virtual_joint" type="fixed">
    <parent link="world"/>
    <child link="base_link"/>
    <origin rpy="0 0 0" xyz="0 0 0"/>
  </joint>
  <joint name="joint_1" type="revolute">
    <parent link="base_link"/>
    <child link="link_1"/>
    <origin rpy="0 0 0" xyz="0.0 0.0 0.19"/>
    <axis xyz="0.0 0.0 1.0"/>
    <limit effort="100.0" lower="-3.14159" upper="3.14159" velocity="1.0"/>
  </joint>
  <joint name="joint_2" type="revolute">
    <parent link="link_1"/>
    <child link="link_2"/>
    <origin rpy="0 0 0" xyz="-0.07 0.026322 0.186322"/>
    <axis xyz="-1.0 -0.0 0.0"/>
    <limit effort="150.0" lower="-1.5708" upper="1.5708" velocity="1.0"/>
  </joint>
  <joint name="joint_3" type="revolute">
    <parent link="link_2"/>
    <child link="link_3"/>
    <origin rpy="0 0 0" xyz="0.0 0.225 0.0"/>
    <axis xyz="1.0 0.0 -0.0"/>
    <limit effort="100.0" lower="-2.0944" upper="2.0944" velocity="1.0"/>
  </joint>
  <joint name="joint_4" type="revolute">
    <parent link="link_3"/>
    <child link="link_4"/>
    <origin rpy="0 0 0" xyz="0.08 0.225 0.0"/>
    <axis xyz="-1.0 -0.0 0.0"/>
    <limit effort="50.0" lower="-2.0944" upper="2.0944" velocity="1.5"/>
  </joint>
  <joint name="joint_5" type="revolute">
    <parent link="link_4"/>
    <child link="link_5"/>
    <origin rpy="0 0 0" xyz="-0.028 0.021812 -4e-06"/>
    <axis xyz="-0.0 1.0 -0.0"/>
    <limit effort="30.0" lower="-3.14159" upper="3.14159" velocity="2.0"/>
  </joint>
  <joint name="link5_to_midpoint" type="fixed">
    <parent link="link_5"/>
    <child link="gripper_mid_point"/>
    <origin rpy="0 0 0" xyz="0 0.075 0"/>
  </joint>
  <joint name="gripperbase_to_armgearright" type="revolute">
    <parent link="link_5"/>
    <child link="gripper_finger_right"/>
    <origin rpy="0 0 0" xyz="0.009742 0.081458 0.0"/>
    <axis xyz="-0.0 0.0 1.0"/>
    <limit effort="10.0" lower="-0.5" upper="0.5" velocity="2.0"/>
  </joint>
  <joint name="gripperbase_to_armgearleft" type="revolute">
    <parent link="link_5"/>
    <child link="gripper_finger_left"/>
    <origin rpy="0 0 0" xyz="-0.009743 0.081458 0.0"/>
    <axis xyz="-0.0 0.0 1.0"/>
    <limit effort="10.0" lower="-0.5" upper="0.5" velocity="2.0"/>
    <mimic joint="gripperbase_to_armgearright" multiplier="-1"/>
  </joint>
</robot>
